Workbook

Sheet Cover
A3: FINNISH ONSHORE WIND PROJECT
A5: Project Finance Model
A8: MODEL OVERVIEW
A9: Item | B9: Value | C9: Unit | D9: Status
A10: Model version | B10: 1.8 | C10: - | D10: nominal, two scenario switches, horizon to 2058, scenario and break-even snapshots, Sources & Checks, standalone BESS tab; BESS CAPEX-saving grid and snapshot checks
A11: Valuation date | B11: 2026 | C11: year | D11: Input
A12: Project COD | B12: =Inputs!B9 -> 2028 | C12: year | D12: Input
A13: Project lifetime | B13: =Inputs!B8 -> 25 | C13: years | D13: Input
A14: Installed capacity | B14: =Inputs!B7 -> 100 | C14: MW | D14: Input
A15: PPA mode | B15: Yes | C15: - | D15: Input
A16: Capture-rate scenario | B16: Base | C16: - | D16: Input
A17: Market price scenario | B17: Base | C17: - | D17: Input
A19: WORKBOOK MAP
A20: Tab | B20: Purpose
A21: Inputs | B21: Core technical, commercial and financing assumptions; every assumption has source/status fields.
A22: Prices | B22: Market-price inputs, capture-rate scenarios and PPA switch.
A23: Production | B23: Annual wind generation (integrated BESS logic switched off; see BESS tab).
A24: Revenue | B24: Merchant/PPA revenue build-up.
A25: Cashflow | B25: Project and equity cash-flow bridge.
A26: Financing | B26: DSCR-based debt sizing and debt schedule.
A27: Taxes | B27: Taxable income, loss carryforward and corporate tax.
A28: Outputs | B28: IRR, NPV, LCOE, DSCR, PPA indifference price, scenario grids and break-even PPA price.
A29: Checks | B29: Model integrity and source-status checks.
A30: Changelog | B30: List of corrections and structural changes since v1.0, plus open items.
A31: Sources & Checks | B31: Validation checks against sources and hand calculations; log of AI use.
A32: BESS | B32: Standalone co-located battery: inputs with sources, cash flows, NPV/IRR, scenario snapshot.

Sheet Inputs
A1: INPUTS
A3: Blue cells are intended for user inputs. Green = sourced/verified. Yellow = own assumption / to verify. Grey = formula.
A5: PROJECT
A6: Parameter | B6: Value | C6: Unit | D6: Source / reference | E6: Status | F6: Base / scenario | G6: Notes | H6: Model use
A7: Installed capacity | B7: 100 | C7: MW | D7: Scaled to typical small Finnish project size. Reference projects: Honkakangas 105 MW and Rajamäenkylä 367 MW (OX2 press release, 1 Apr 2025), Pahkakoski 186 MW (NIB loan, 14 Dec 2023), Lestijärvi 455 MW, the largest Finnish wind farm built to date (Renewables Finland, wind power statistics 2025). | E7: own assumption | G7: Replace with project size. | H7: Production
A8: Project lifetime | B8: 25 | C8: years | D8: Renewables Finland / Finnish Wind Power Association, "Tuulivoimalan purkamisen kustannukset", 9 Aug 2023: calculated lifetime 35 years for turbines from the 2020s, 20-30 years for older ones. Base case 25 years chosen conservatively; sensitivity 20 and 30 years. Industry association source; lease and permit duration not checked. Danish Energy Agency (2026), sheet 20: technical lifetime 27 years (2025) and 30 years from 2030, depending on wind conditions and turbine design class. | E8: source-based | G8: Economic operating life. | H8: Production, Cashflow
A9: Commercial operation date | B9: 2028 | C9: year | D9: FID assumed in H2 2026, construction about 15 to 24 months. Reference: OX2 FID 1 Apr 2025 with completion 2027 (Honkakangas) and 2028 (Rajamäenkylä); NIB loan Pahkakosken Energia Oy 14 Dec 2023 with completion expected Aug 2025. Danish Energy Agency (2026), sheet 20: construction time 1.5 years from FID to commissioning; planning from idea to construction start typically 2 to 3 years. | E9: own assumption | G9: COD assumption. | H9: Production, Cashflow
A10: Net capacity factor | B10: 0.35 | C10: % | D10: OX2 press release, 1 Apr 2025: about 1.6 TWh per year from 472 MW = 38.7 % (own calculation; probability level not stated). NIB loan Pahkakosken Energia Oy, 14 Dec 2023: 516 GWh per year at 90 % probability for 186 MW = 31.7 % (P90). Own analysis of ENTSO-E data: Finnish fleet average 26-30 % (2023-2025, older turbines). 35 % chosen as net P50 estimate between the sources; sensitivity 32 to 38 %. Danish Energy Agency (2026), sheet 20: 3,500 full load hours (capacity factor 40.0 %) for 2025, average for expected Danish wind farm locations including wake losses; 3,600 hours for 2030. | E10: source-based | G10: Use net output factor after availability/losses. | H10: Production
A11: Curtailment | B11: 0.05 | C11: % | D11: Own analysis of Finnish day-ahead prices and ENTSO-E wind generation (Actual Generation per Production Type, FI) (project data; https://transparency.entsoe.eu/, accesed 1.10.2026): share of wind energy produced in negative-price hours 8.2 % (2023), 11.5 % (2024), 6.5 % (2025), 1.8 % (last 12 months to Sep 2026). Base 5 % chosen between the recent value and the 2023-2025 average (8.8 %); future share is a judgement within this range. Sensitivity 2 to 10 %. Capture rates are taken from the curtailed variant to avoid double counting | E11: source-based | G11: Base case corresponds to a PPA with no settlement in negative-price hours (seller bears the lost volume). Newer contracts keep settling with a EUR 0/MWh floor but at a lower strike; Modo Energy (Oct 2025, Spanish solar PPAs) estimates a price difference of at least about EUR 3/MWh between the two structures. 5 % curtailment × EUR 50/MWh = about EUR 2.5/MWh (own calculation), i.e. broadly equivalent. Sensitivity B11 = 0 only valid together with a lower PPA price. Grid curtailment by Fingrid not included. | H11: Production
A12: CAPEX
A13: Parameter | B13: Value | C13: Unit | D13: Source / reference | E13: Status | F13: Base / scenario | G13: Notes | H13: Model use
A14: Wind CAPEX | B14: 1500 | C14: €/kW | D14: OX2 press release, FID 1 Apr 2025: more than EUR 700m for 472 MW (about 1.48 EUR m/MW, lower bound). NIB loan Pahkakosken Energia Oy, 14 Dec 2023: capex EUR 230m for 186 MW (1.24 EUR m/MW). WindEurope Autumn 2026, p. 19: EU onshore nearly EUR 6bn for 3.8 GW (about 1.58 EUR m/MW, own calculation from rounded figures). 1,500 EUR/kW selected between the 2025 OX2 FIDs (1.44-1.48 EUR m/MW: Dec 2025, about EUR 400m for 277 MW; Apr 2025, more than EUR 700m for 472 MW) and WindEurope 2026 (about 1.58 EUR m/MW). Cross-check: IRENA (2026), Fig. 2.4: Finland TIC 2025 USD 1,480/kW. | E14: source-based | G14: Base 1,500 EUR/kW in real 2026 EUR. Sensitivity 1,250 to 1,650 EUR/kW. Treated as all-in investment at FID (row 16 stays empty); scope of the sources not stated, to verify. | H14: Cashflow (CAPEX)
A15: BESS CAPEX | C15: €/kWh | E15: n/a | G15: Not used: integrated BESS switched off (B24 = 0); battery evaluated standalone in tab BESS. Only used if BESS capacity > 0. Enter in real 2026 EUR; indexed with inflation (B63). | H15: Cashflow (CAPEX)
A16: Development / other CAPEX | B16: 0 | C16: €/kW | D16: Assumed to be 0 and all CAPEX covered in row 14 | E16: own assumption | G16: Optional project-specific allowance. Enter in real 2026 EUR; indexed with inflation (B63). | H16: Cashflow (CAPEX)
A17: OPEX & LEASE
A18: Parameter | B18: Value | C18: Unit | D18: Source / reference | E18: Status | F18: Base / scenario | G18: Notes | H18: Model use
A19: Fixed OPEX | B19: 39000 | C19: €/MW/year | D19: Value 39,000 EUR/MW/yr = 39 EUR/kW/yr (compare B19 + B21 = 44 EUR/kW/yr). Generic O&M about 35 EUR/kW/yr: NREL, Cost of Wind Energy Review 2024 Edition, US land-based reference plant (3.3 MW) about USD 43/kW/yr (scope not checked); Wind Energy - The Facts (EWEA): O&M 1.2-1.5 EUR cent/kWh over turbine life (Germany, Spain, UK, Denmark) = about 37-46 EUR/kW/yr at 35 % capacity factor (own calculation). Nordic cross-checks: Danish Energy Agency, Technology Data for Generation of Electricity and District Heating, version 0019 (Aug 2026), sheet 20 Onshore turbines, 2025 values in 2020 prices: fixed O&M 17.4 kEUR/MW/yr plus variable O&M 2.06 EUR/MWh = about 24.6 EUR/kW/yr at 3,500 full load hours (own calculation; land rent and property tax not included; not inflated to 2026); Paaso and Khosravi (2021), Energy Engineering 118(4), Aalto University, use O&M of 2 % of investment cost per year citing the Finnish Wind Power Association (2020; original page no longer available) = 31 EUR/kW/yr at 1,550 EUR/kW (own calculation; scope not stated). European study: KIC InnoEnergy / BVG Associates, "Future renewable energy costs: onshore wind", Sep 2014 (50 MW reference wind farm): OPEX 42 EUR/kW/yr (high wind site) and 36 EUR/kW/yr (low wind site) in real end-2013 prices, including land lease and community funds, excluding insurance and transmission charges; not inflated to 2026. Plus Finnish property tax about 4 EUR/kW/yr: Megatuuli Oy, Honkalankangas project presentation, 8 Nov 2021: about 30,000 EUR per turbine per year, 640,000 EUR per turbine over 30 years (age reduction); about 3-5 EUR/kW/yr at 6.5 MW per turbine (own calculation). The US source may already include property tax. Property tax cross-check: Renewables Finland, "Effects to the economy" (page last updated 24 Sep 2024, accessed 2 Oct 2026): power plant property tax rate max. 3.1 % (wind farms > 10 MVA); tax base = foundation, tower and nacelle shell only (about 30 % of turbine investment cost); first-year taxable value 75 %, age discount 2.5 % p.a. down to a floor of 40 %; observed first-year property tax EUR 20,000-35,000 per turbine. At 6.5 MW per turbine = about 3-5.4 EUR/kW in year 1 (own calculation); formula example at EUR 1m/MW gives about 7 EUR/kW. Lifetime average about 70 % of year 1 because of the age discount (own calculation). About 4 EUR/kW/yr kept, indexed with inflation (simplification: age discount and construction cost index not modelled separately). No Finnish primary O&M measurement found. | E19: source-based | G19: All O&M entered as fixed (variable OPEX = 0). Sensitivity band +/-30 % on B19 + B21 (about 31,000 to 57,000 EUR/MW/yr). No real cost decline assumed. Enter in real 2026 EUR; indexed with inflation (B63). | H19: Cashflow
A20: Variable OPEX | B20: 0 | C20: €/MWh | D20: Variable OPEX assumed to be small and included in fixed OPEX | E20: own assumption | G20: Optional variable cost. Enter in real 2026 EUR; indexed with inflation (B63). | H20: Cashflow
A21: Land lease / rent | B21: 5000 | C21: €/MW/year | D21: Value 5,000 EUR/MW/yr = 5 EUR/kW/yr. Finnish Forest Association, "Wind power generates profits from state-owned land", 12 Sep 2014: landowners are paid EUR 5,000 to 15,000 per year per turbine (media ballpark figure quoted by Metsähallitus, actual rate not disclosed), equal to about 0.8 to 5.0 kEUR/MW/yr for 3 to 6.5 MW turbines (own calculation). Second anchor: cost split in Wind Energy - The Facts (EWEA), land rent about 13 % of O&M = about 5 EUR/kW/yr (own calculation). Value set at the upper end of the Finnish range (conservative). Qualitative support: Renewables Finland: lease higher than forestry return; Megatuuli Oy, 8 Nov 2021: up to two to three times forestry income. Lease contracts are not public; media figure from 2014. | E21: source-based | G21: Document local lease basis. Enter in real 2026 EUR; indexed with inflation (B63). | H21: Cashflow
A22: BESS
A23: Parameter | B23: Value | C23: Unit | D23: Source / reference | E23: Status | F23: Base / scenario | G23: Notes | H23: Model use
A24: BESS energy capacity | B24: 0 | C24: MWh | E24: own assumption | G24: Set to 0 if no BESS. v1.7: kept at 0; the BESS is evaluated standalone in tab BESS. | H24: Production, Cashflow
A25: BESS round-trip efficiency | B25: 0.85 | C25: % | E25: n/a | G25: Not used: integrated BESS switched off (B24 = 0); battery evaluated standalone in tab BESS. Only relevant if BESS is modelled. | H25: Production, Revenue
A26: BESS cycles | B26: 0 | C26: cycles/year | E26: n/a | G26: Not used: integrated BESS switched off (B24 = 0); battery evaluated standalone in tab BESS.Full-load discharge cycles per year; drives BESS arbitrage volume (Production). | H26: Production, Revenue
A27: TAX
A28: Parameter | B28: Value | C28: Unit | D28: Source / reference | E28: Status | F28: Base / scenario | G28: Notes | H28: Model use
A29: Corporate income tax rate | B29: 0.2 | C29: % | D29: vero.fi, Your tax handbook in Finland: 20 % (accessed 1 Oct 2026) | E29: verified | G29: Current law 20 %. Government budget proposal for 2027 of 17 Sep 2026 (valtioneuvosto.fi): 18 % from 2027, loss carry-forward 25 years; not yet law. Loss carry-forward modelled without expiry, consistent with Government proposal HE 151/2026 (25 years for losses from tax year 2026). Own sensitivity: current-law 10-year expiry about −1.2 EUR m NPV; 18 % rate about +0.2 EUR m. | H29: Taxes
A30: FINANCING
A31: Parameter | B31: Value | C31: Unit | D31: Source / reference | E31: Status | F31: Base / scenario | G31: Notes | H31: Model use
A32: Target minimum DSCR | B32: 1.3 | C32: x | D32: Typical minimum DSCR on P50: 1.25-1.35x contracted, 1.40-1.50x with significant merchant exposure (Intellifields, renewable energy financial model guide, 2026); 1.35-1.45x contracted renewables, 1.60x+ merchant (ibinterviewquestions.com, Aug 2026). Secondary sources, no Finnish term sheet available. 1.30x chosen for 100 % PPA over the full debt tenor (B44 = B34) with an investment-grade offtaker. | E32: own assumption | F32: Base (merchant case), PPA case: 1.4 | G32: Single DSCR applied to all debt years. Scenario-dependent, set manually: 1.30 (100 % PPA, PPA tenor = debt tenor), 1.40 (65 % PPA), 1.60 (merchant, together with WACC 7 %). P90 sizing not modelled. Sensitivity 1.25 to 1.40. | H32: Financing
A33: Debt interest rate | B33: 0.0575 | C33: % | D33: EUR 10-year interest rate swap (vs 6M EURIBOR) about 3.7 % (Investing.com / BlueGamma, 28-29 Sep 2026). Lending margin 2.0 %: IRENA, "The cost of financing for renewable power", May 2023 (global baseline for large private infrastructure debt). as a proxy; the sculpted 15-year loan has an average life of about 8.7 years (own calculation from Financing), so the 10Y swap is slightly conservative.. All-in 5.75 % nominal; sensitivity 4.75 to 6.75 %. Hedging cost, fees and Finland-specific margin not checked (accessed 2 Oct 2026) | E33: source-based | G33: Debt rate enters project NPV only via the WACC (B38), which is not linked to this cell. When varying B33, adjust B38 by about 0.38 pp per 1 pp change (47 % gearing × (1 - 20 % tax), see D38) | H33: Financing
A34: Debt tenor | B34: 15 | C34: years | D34: Typical tenor for contracted onshore wind 15-18 years (Intellifields, 2026). 15 years = lower end, leaves 10-year tail to the 25-year life; sensitivity 18 years. Debt tenor equal to the 15-year PPA | E34: own assumption | G34: Debt tenor from first drawdown/COD. | H34: Financing
A35: Debt sizing horizon | B35: 15 | C35: years | D35: set equal to debt tenor | E35: own assumption | G35: Years of CFADS used for sizing; limited to the debt tenor. | H35: Financing
A36: RETURNS
A37: Parameter | B37: Value | C37: Unit | D37: Source / reference | E37: Status | F37: Base / scenario | G37: Notes | H37: Model use
A38: Discount rate / WACC | B38: 0.06 | C38: % | D38: CAPM build-up (own calculation): risk-free 3.58 % (Finland 10Y government bond, 18 Aug 2026, Trading Economics); equity risk premium 4.23 % (Damodaran, implied ERP, Jan 2026); unlevered beta 0.47 (Damodaran, Green & Renewable Energy, US dataset, Jan 2026), relevered at 47 % gearing = 0.80; cost of equity about 7.0 %. WACC = 53 % × 7.0 % + 47 % × 5.75 % × (1 - 20 %) = about 5.9 % nominal after tax. Cross-check: IRENA (2026), ch. 1: about 3 % real for fully contracted projects; merchant WACC roughly double (citing BNEF 2026). 6 % used for the PPA case, 7 % for the merchant case. | E38: own assumption | G38: Nominal WACC (cash flows are nominal). Used for project NPV and LCOE. Scenario-dependent: about 6 % nominal for the PPA case (Cover!B15 = Yes), 7 % for the merchant case; set manually together with B32. Affects NPV and LCOE only, not the cash flows. Sensitivity 5 to 8 %. Model run: 1 pp lower WACC reduces LCOE by about 3 EUR/MWh (own calculation) | H38: Outputs
A39: Target equity IRR | B39: 0.1 | C39: % | D39: CAPM cost of equity about 7.0 % (see D38) plus own premium of 2-3 pp for a single unlisted asset with construction and volume risk = 9-10 %. 10 % used (upper end). Sensitivity 8 to 12 %. | E39: own assumption | G39: Beta from Damodaran US dataset (European dataset not checked); no Finland country risk premium added (AA-rated, to verify). | H39: Checks
A40: PPA price | B40: 50 | C40: €/MWh | D40: Upper end of observed market levels: LevelTen Energy PPA Price Index Europe Q1 2026, top-quartile (P25) wind offers EUR 49.95/MWh, Finland and Portugal only, seller offers not transactions (via SR Inc NZCB Europe VPPA Opportunity Index 2026 Q1). Lower reference: KYOS PPA Insights No. 19 (Jun 2026), Finland, 2027-2036: onshore wind capture price 36.1 EUR/MWh, P25 PPA estimate 28.9 EUR/MWh (baseload 60.0 EUR/MWh). Pexapark Euro Composite Jul 2026: EUR 45/MWh (all technologies, Europe). Break-even PPA implied by recent OX2 FIDs about 62-67 EUR/MWh (own model runs, see Sources & Checks). Fixed nominal; sensitivity 25 to 80 EUR/MWh (accessed 2 Oct 2026). Model break-even for this 100 MW case: 70.35 (NPV = 0) and 73.94 EUR/MWh (equity IRR 10 %), Outputs rows 28-32. LevelTen Q2 2026 (23 Jul 2026): Finnish wind prices held steady (leveltenenergy.com, accessed 4 Oct 2026). | E40: own assumption | G40: Fixed nominal (B64 = No). Chosen as upper bound for robustness, not as a data-centre premium. Break-even PPA price for the base case: see Outputs / Sources & Checks. | H40: Revenue
A41: PPA STRUCTURE
A42: Parameter | B42: Value | C42: Unit | D42: Source / reference | E42: Status | F42: Base / scenario | G42: Notes | H42: Model use
...

Sheet Prices
A1: PRICES
A3: Capture-rate scenario | B3: =Cover!B16 -> Base
A4: PPA mode | B4: =Cover!B15 -> Yes
A5: Market price scenario | B5: =Cover!B17 -> Base
A6: ANNUAL MARKET PRICE & CAPTURE RATE INPUTS | R6: PRICE PATH ANCHORS (real 2026 EUR/MWh, linked to Inputs)
A7: Year | B7: Market price Base (real 2026 EUR/MWh) | C7: Low capture | D7: Base capture | E7: High capture | F7: Selected capture | G7: Realized price (nominal) | H7: PPA price (nominal) | I7: Selected revenue price (nominal) | J7: PPA volume share | K7: PPA window (1/0) | L7: Inflation index (2026 = 1) | M7: PPA index factor | N7: Market price Low (real 2026 EUR/MWh) | O7: Market price High (real 2026 EUR/MWh) | P7: Selected market price (real 2026 EUR/MWh) | R7: Anchor year | S7: Base | T7: Low | U7: High | V7: Inputs reference
A8: 2026 | B8: =IF($A8>=$R$12,S$12,INDEX(S$8:S$12,MATCH($A8,$R$8:$R$12,1))+(INDEX(S$8:S$12,MATCH($A8,$R$8:$R$12,1)+1)-INDEX(S$8:S$12,MATCH($A8,$R$8:$R$12,1)))*($A8-INDEX($R$8:$R$12,MATCH($A8,$R$8:$R$12,1)))/(INDEX($R$8:$R$12,MATCH($A8,$R$8:$R$12,1)+1)-INDEX($R$8:$R$12,MATCH($A8,$R$8:$R$12,1)))) -> 55.78 | C8: =Inputs!$B$79 -> 0.5 | D8: =Inputs!$B$80 -> 0.6 | E8: =Inputs!$B$81 -> 0.7 | F8: =IF($B$3="Low",C8,IF($B$3="High",E8,D8)) -> 0.6 | G8: =P8*F8*L8 -> 33.468 | H8: =Inputs!B40*M8 -> 50 | I8: =J8*H8+(1-J8)*G8 -> 33.468 | J8: =IF(AND($B$4="Yes",K8=1),Inputs!$B$43,0) -> 0 | K8: =IF(AND(A8>=Inputs!$B$9,A8<Inputs!$B$9+Inputs!$B$44),1,0) -> 0 | L8: =(1+Inputs!$B$63)^(A8-$A$8) -> 1 | M8: =IF(Inputs!$B$64="Yes",L8,1) -> 1 | N8: =IF($A8>=$R$12,T$12,INDEX(T$8:T$12,MATCH($A8,$R$8:$R$12,1))+(INDEX(T$8:T$12,MATCH($A8,$R$8:$R$12,1)+1)-INDEX(T$8:T$12,MATCH($A8,$R$8:$R$12,1)))*($A8-INDEX($R$8:$R$12,MATCH($A8,$R$8:$R$12,1)))/(INDEX($R$8:$R$12,MATCH($A8,$R$8:$R$12,1)+1)-INDEX($R$8:$R$12,MATCH($A8,$R$8:$R$12,1)))) -> 55.78 | O8: =IF($A8>=$R$12,U$12,INDEX(U$8:U$12,MATCH($A8,$R$8:$R$12,1))+(INDEX(U$8:U$12,MATCH($A8,$R$8:$R$12,1)+1)-INDEX(U$8:U$12,MATCH($A8,$R$8:$R$12,1)))*($A8-INDEX($R$8:$R$12,MATCH($A8,$R$8:$R$12,1)))/(INDEX($R$8:$R$12,MATCH($A8,$R$8:$R$12,1)+1)-INDEX($R$8:$R$12,MATCH($A8,$R$8:$R$12,1)))) -> 55.78 | P8: =IF($B$5="Low",N8,IF($B$5="High",O8,B8)) -> 55.78 | R8: 2026 | S8: =Inputs!$B$68 -> 55.78 | T8: =Inputs!$B$68 -> 55.78 | U8: =Inputs!$B$68 -> 55.78 | V8: Inputs 68 (all)
A9: 2027 | B9: =IF($A9>=$R$12,S$12,INDEX(S$8:S$12,MATCH($A9,$R$8:$R$12,1))+(INDEX(S$8:S$12,MATCH($A9,$R$8:$R$12,1)+1)-INDEX(S$8:S$12,MATCH($A9,$R$8:$R$12,1)))*($A9-INDEX($R$8:$R$12,MATCH($A9,$R$8:$R$12,1)))/(INDEX($R$8:$R$12,MATCH($A9,$R$8:$R$12,1)+1)-INDEX($R$8:$R$12,MATCH($A9,$R$8:$R$12,1)))) -> 54.81 | C9: =Inputs!$B$79 -> 0.5 | D9: =Inputs!$B$80 -> 0.6 | E9: =Inputs!$B$81 -> 0.7 | F9: =IF($B$3="Low",C9,IF($B$3="High",E9,D9)) -> 0.6 | G9: =P9*F9*L9 -> 33.54372 | H9: =Inputs!B40*M9 -> 50 | I9: =J9*H9+(1-J9)*G9 -> 33.54372 | J9: =IF(AND($B$4="Yes",K9=1),Inputs!$B$43,0) -> 0 | K9: =IF(AND(A9>=Inputs!$B$9,A9<Inputs!$B$9+Inputs!$B$44),1,0) -> 0 | L9: =(1+Inputs!$B$63)^(A9-$A$8) -> 1.02 | M9: =IF(Inputs!$B$64="Yes",L9,1) -> 1 | N9: =IF($A9>=$R$12,T$12,INDEX(T$8:T$12,MATCH($A9,$R$8:$R$12,1))+(INDEX(T$8:T$12,MATCH($A9,$R$8:$R$12,1)+1)-INDEX(T$8:T$12,MATCH($A9,$R$8:$R$12,1)))*($A9-INDEX($R$8:$R$12,MATCH($A9,$R$8:$R$12,1)))/(INDEX($R$8:$R$12,MATCH($A9,$R$8:$R$12,1)+1)-INDEX($R$8:$R$12,MATCH($A9,$R$8:$R$12,1)))) -> 54.81 | O9: =IF($A9>=$R$12,U$12,INDEX(U$8:U$12,MATCH($A9,$R$8:$R$12,1))+(INDEX(U$8:U$12,MATCH($A9,$R$8:$R$12,1)+1)-INDEX(U$8:U$12,MATCH($A9,$R$8:$R$12,1)))*($A9-INDEX($R$8:$R$12,MATCH($A9,$R$8:$R$12,1)))/(INDEX($R$8:$R$12,MATCH($A9,$R$8:$R$12,1)+1)-INDEX($R$8:$R$12,MATCH($A9,$R$8:$R$12,1)))) -> 54.81 | P9: =IF($B$5="Low",N9,IF($B$5="High",O9,B9)) -> 54.81 | R9: 2028 | S9: =IF(Inputs!$B$69="",S8+(S10-S8)*($R9-$R8)/($R10-$R8),Inputs!$B$69) -> 53.84 | T9: =IF(Inputs!$B$69="",T8+(T10-T8)*($R9-$R8)/($R10-$R8),Inputs!$B$69) -> 53.84 | U9: =IF(Inputs!$B$69="",U8+(U10-U8)*($R9-$R8)/($R10-$R8),Inputs!$B$69) -> 53.84 | V9: Inputs 69 (blank = interpolated)
A10: 2028 | B10: =IF($A10>=$R$12,S$12,INDEX(S$8:S$12,MATCH($A10,$R$8:$R$12,1))+(INDEX(S$8:S$12,MATCH($A10,$R$8:$R$12,1)+1)-INDEX(S$8:S$12,MATCH($A10,$R$8:$R$12,1)))*($A10-INDEX($R$8:$R$12,MATCH($A10,$R$8:$R$12,1)))/(INDEX($R$8:$R$12,MATCH($A10,$R$8:$R$12,1)+1)-INDEX($R$8:$R$12,MATCH($A10,$R$8:$R$12,1)))) -> 53.84 | C10: =Inputs!$B$79 -> 0.5 | D10: =Inputs!$B$80 -> 0.6 | E10: =Inputs!$B$81 -> 0.7 | F10: =IF($B$3="Low",C10,IF($B$3="High",E10,D10)) -> 0.6 | G10: =P10*F10*L10 -> 33.609082 | H10: =Inputs!B40*M10 -> 50 | I10: =J10*H10+(1-J10)*G10 -> 50 | J10: =IF(AND($B$4="Yes",K10=1),Inputs!$B$43,0) -> 1 | K10: =IF(AND(A10>=Inputs!$B$9,A10<Inputs!$B$9+Inputs!$B$44),1,0) -> 1 | L10: =(1+Inputs!$B$63)^(A10-$A$8) -> 1.0404 | M10: =IF(Inputs!$B$64="Yes",L10,1) -> 1 | N10: =IF($A10>=$R$12,T$12,INDEX(T$8:T$12,MATCH($A10,$R$8:$R$12,1))+(INDEX(T$8:T$12,MATCH($A10,$R$8:$R$12,1)+1)-INDEX(T$8:T$12,MATCH($A10,$R$8:$R$12,1)))*($A10-INDEX($R$8:$R$12,MATCH($A10,$R$8:$R$12,1)))/(INDEX($R$8:$R$12,MATCH($A10,$R$8:$R$12,1)+1)-INDEX($R$8:$R$12,MATCH($A10,$R$8:$R$12,1)))) -> 53.84 | O10: =IF($A10>=$R$12,U$12,INDEX(U$8:U$12,MATCH($A10,$R$8:$R$12,1))+(INDEX(U$8:U$12,MATCH($A10,$R$8:$R$12,1)+1)-INDEX(U$8:U$12,MATCH($A10,$R$8:$R$12,1)))*($A10-INDEX($R$8:$R$12,MATCH($A10,$R$8:$R$12,1)))/(INDEX($R$8:$R$12,MATCH($A10,$R$8:$R$12,1)+1)-INDEX($R$8:$R$12,MATCH($A10,$R$8:$R$12,1)))) -> 53.84 | P10: =IF($B$5="Low",N10,IF($B$5="High",O10,B10)) -> 53.84 | R10: 2030 | S10: =Inputs!$B$70 -> 48.67 | T10: =Inputs!$B$73 -> 34.7 | U10: =Inputs!$B$76 -> 56.6 | V10: Base 70 / Low 73 / High 76
A11: 2029 | B11: =IF($A11>=$R$12,S$12,INDEX(S$8:S$12,MATCH($A11,$R$8:$R$12,1))+(INDEX(S$8:S$12,MATCH($A11,$R$8:$R$12,1)+1)-INDEX(S$8:S$12,MATCH($A11,$R$8:$R$12,1)))*($A11-INDEX($R$8:$R$12,MATCH($A11,$R$8:$R$12,1)))/(INDEX($R$8:$R$12,MATCH($A11,$R$8:$R$12,1)+1)-INDEX($R$8:$R$12,MATCH($A11,$R$8:$R$12,1)))) -> 51.255 | C11: =Inputs!$B$79 -> 0.5 | D11: =Inputs!$B$80 -> 0.6 | E11: =Inputs!$B$81 -> 0.7 | F11: =IF($B$3="Low",C11,IF($B$3="High",E11,D11)) -> 0.6 | G11: =P11*F11*L11 -> 32.63533 | H11: =Inputs!B40*M11 -> 50 | I11: =J11*H11+(1-J11)*G11 -> 50 | J11: =IF(AND($B$4="Yes",K11=1),Inputs!$B$43,0) -> 1 | K11: =IF(AND(A11>=Inputs!$B$9,A11<Inputs!$B$9+Inputs!$B$44),1,0) -> 1 | L11: =(1+Inputs!$B$63)^(A11-$A$8) -> 1.061208 | M11: =IF(Inputs!$B$64="Yes",L11,1) -> 1 | N11: =IF($A11>=$R$12,T$12,INDEX(T$8:T$12,MATCH($A11,$R$8:$R$12,1))+(INDEX(T$8:T$12,MATCH($A11,$R$8:$R$12,1)+1)-INDEX(T$8:T$12,MATCH($A11,$R$8:$R$12,1)))*($A11-INDEX($R$8:$R$12,MATCH($A11,$R$8:$R$12,1)))/(INDEX($R$8:$R$12,MATCH($A11,$R$8:$R$12,1)+1)-INDEX($R$8:$R$12,MATCH($A11,$R$8:$R$12,1)))) -> 44.27 | O11: =IF($A11>=$R$12,U$12,INDEX(U$8:U$12,MATCH($A11,$R$8:$R$12,1))+(INDEX(U$8:U$12,MATCH($A11,$R$8:$R$12,1)+1)-INDEX(U$8:U$12,MATCH($A11,$R$8:$R$12,1)))*($A11-INDEX($R$8:$R$12,MATCH($A11,$R$8:$R$12,1)))/(INDEX($R$8:$R$12,MATCH($A11,$R$8:$R$12,1)+1)-INDEX($R$8:$R$12,MATCH($A11,$R$8:$R$12,1)))) -> 55.22 | P11: =IF($B$5="Low",N11,IF($B$5="High",O11,B11)) -> 51.255 | R11: 2040 | S11: =Inputs!$B$71 -> 39.8 | T11: =Inputs!$B$74 -> 32.6 | U11: =Inputs!$B$77 -> 56.6 | V11: Base 71 / Low 74 / High 77
A12: 2030 | B12: =IF($A12>=$R$12,S$12,INDEX(S$8:S$12,MATCH($A12,$R$8:$R$12,1))+(INDEX(S$8:S$12,MATCH($A12,$R$8:$R$12,1)+1)-INDEX(S$8:S$12,MATCH($A12,$R$8:$R$12,1)))*($A12-INDEX($R$8:$R$12,MATCH($A12,$R$8:$R$12,1)))/(INDEX($R$8:$R$12,MATCH($A12,$R$8:$R$12,1)+1)-INDEX($R$8:$R$12,MATCH($A12,$R$8:$R$12,1)))) -> 48.67 | C12: =Inputs!$B$79 -> 0.5 | D12: =Inputs!$B$80 -> 0.6 | E12: =Inputs!$B$81 -> 0.7 | F12: =IF($B$3="Low",C12,IF($B$3="High",E12,D12)) -> 0.6 | G12: =P12*F12*L12 -> 31.609184 | H12: =Inputs!B40*M12 -> 50 | I12: =J12*H12+(1-J12)*G12 -> 50 | J12: =IF(AND($B$4="Yes",K12=1),Inputs!$B$43,0) -> 1 | K12: =IF(AND(A12>=Inputs!$B$9,A12<Inputs!$B$9+Inputs!$B$44),1,0) -> 1 | L12: =(1+Inputs!$B$63)^(A12-$A$8) -> 1.0824322 | M12: =IF(Inputs!$B$64="Yes",L12,1) -> 1 | N12: =IF($A12>=$R$12,T$12,INDEX(T$8:T$12,MATCH($A12,$R$8:$R$12,1))+(INDEX(T$8:T$12,MATCH($A12,$R$8:$R$12,1)+1)-INDEX(T$8:T$12,MATCH($A12,$R$8:$R$12,1)))*($A12-INDEX($R$8:$R$12,MATCH($A12,$R$8:$R$12,1)))/(INDEX($R$8:$R$12,MATCH($A12,$R$8:$R$12,1)+1)-INDEX($R$8:$R$12,MATCH($A12,$R$8:$R$12,1)))) -> 34.7 | O12: =IF($A12>=$R$12,U$12,INDEX(U$8:U$12,MATCH($A12,$R$8:$R$12,1))+(INDEX(U$8:U$12,MATCH($A12,$R$8:$R$12,1)+1)-INDEX(U$8:U$12,MATCH($A12,$R$8:$R$12,1)))*($A12-INDEX($R$8:$R$12,MATCH($A12,$R$8:$R$12,1)))/(INDEX($R$8:$R$12,MATCH($A12,$R$8:$R$12,1)+1)-INDEX($R$8:$R$12,MATCH($A12,$R$8:$R$12,1)))) -> 56.6 | P12: =IF($B$5="Low",N12,IF($B$5="High",O12,B12)) -> 48.67 | R12: 2050 | S12: =Inputs!$B$72 -> 45.6 | T12: =Inputs!$B$75 -> 37.4 | U12: =Inputs!$B$78 -> 56.6 | V12: Base 72 / Low 75 / High 78
A13: 2031 | B13: =IF($A13>=$R$12,S$12,INDEX(S$8:S$12,MATCH($A13,$R$8:$R$12,1))+(INDEX(S$8:S$12,MATCH($A13,$R$8:$R$12,1)+1)-INDEX(S$8:S$12,MATCH($A13,$R$8:$R$12,1)))*($A13-INDEX($R$8:$R$12,MATCH($A13,$R$8:$R$12,1)))/(INDEX($R$8:$R$12,MATCH($A13,$R$8:$R$12,1)+1)-INDEX($R$8:$R$12,MATCH($A13,$R$8:$R$12,1)))) -> 47.783 | C13: =Inputs!$B$79 -> 0.5 | D13: =Inputs!$B$80 -> 0.6 | E13: =Inputs!$B$81 -> 0.7 | F13: =IF($B$3="Low",C13,IF($B$3="High",E13,D13)) -> 0.6 | G13: =P13*F13*L13 -> 31.653776 | H13: =Inputs!B40*M13 -> 50 | I13: =J13*H13+(1-J13)*G13 -> 50 | J13: =IF(AND($B$4="Yes",K13=1),Inputs!$B$43,0) -> 1 | K13: =IF(AND(A13>=Inputs!$B$9,A13<Inputs!$B$9+Inputs!$B$44),1,0) -> 1 | L13: =(1+Inputs!$B$63)^(A13-$A$8) -> 1.1040808 | M13: =IF(Inputs!$B$64="Yes",L13,1) -> 1 | N13: =IF($A13>=$R$12,T$12,INDEX(T$8:T$12,MATCH($A13,$R$8:$R$12,1))+(INDEX(T$8:T$12,MATCH($A13,$R$8:$R$12,1)+1)-INDEX(T$8:T$12,MATCH($A13,$R$8:$R$12,1)))*($A13-INDEX($R$8:$R$12,MATCH($A13,$R$8:$R$12,1)))/(INDEX($R$8:$R$12,MATCH($A13,$R$8:$R$12,1)+1)-INDEX($R$8:$R$12,MATCH($A13,$R$8:$R$12,1)))) -> 34.49 | O13: =IF($A13>=$R$12,U$12,INDEX(U$8:U$12,MATCH($A13,$R$8:$R$12,1))+(INDEX(U$8:U$12,MATCH($A13,$R$8:$R$12,1)+1)-INDEX(U$8:U$12,MATCH($A13,$R$8:$R$12,1)))*($A13-INDEX($R$8:$R$12,MATCH($A13,$R$8:$R$12,1)))/(INDEX($R$8:$R$12,MATCH($A13,$R$8:$R$12,1)+1)-INDEX($R$8:$R$12,MATCH($A13,$R$8:$R$12,1)))) -> 56.6 | P13: =IF($B$5="Low",N13,IF($B$5="High",O13,B13)) -> 47.783
A14: 2032 | B14: =IF($A14>=$R$12,S$12,INDEX(S$8:S$12,MATCH($A14,$R$8:$R$12,1))+(INDEX(S$8:S$12,MATCH($A14,$R$8:$R$12,1)+1)-INDEX(S$8:S$12,MATCH($A14,$R$8:$R$12,1)))*($A14-INDEX($R$8:$R$12,MATCH($A14,$R$8:$R$12,1)))/(INDEX($R$8:$R$12,MATCH($A14,$R$8:$R$12,1)+1)-INDEX($R$8:$R$12,MATCH($A14,$R$8:$R$12,1)))) -> 46.896 | C14: =Inputs!$B$79 -> 0.5 | D14: =Inputs!$B$80 -> 0.6 | E14: =Inputs!$B$81 -> 0.7 | F14: =IF($B$3="Low",C14,IF($B$3="High",E14,D14)) -> 0.6 | G14: =P14*F14*L14 -> 31.687508 | H14: =Inputs!B40*M14 -> 50 | I14: =J14*H14+(1-J14)*G14 -> 50 | J14: =IF(AND($B$4="Yes",K14=1),Inputs!$B$43,0) -> 1 | K14: =IF(AND(A14>=Inputs!$B$9,A14<Inputs!$B$9+Inputs!$B$44),1,0) -> 1 | L14: =(1+Inputs!$B$63)^(A14-$A$8) -> 1.1261624 | M14: =IF(Inputs!$B$64="Yes",L14,1) -> 1 | N14: =IF($A14>=$R$12,T$12,INDEX(T$8:T$12,MATCH($A14,$R$8:$R$12,1))+(INDEX(T$8:T$12,MATCH($A14,$R$8:$R$12,1)+1)-INDEX(T$8:T$12,MATCH($A14,$R$8:$R$12,1)))*($A14-INDEX($R$8:$R$12,MATCH($A14,$R$8:$R$12,1)))/(INDEX($R$8:$R$12,MATCH($A14,$R$8:$R$12,1)+1)-INDEX($R$8:$R$12,MATCH($A14,$R$8:$R$12,1)))) -> 34.28 | O14: =IF($A14>=$R$12,U$12,INDEX(U$8:U$12,MATCH($A14,$R$8:$R$12,1))+(INDEX(U$8:U$12,MATCH($A14,$R$8:$R$12,1)+1)-INDEX(U$8:U$12,MATCH($A14,$R$8:$R$12,1)))*($A14-INDEX($R$8:$R$12,MATCH($A14,$R$8:$R$12,1)))/(INDEX($R$8:$R$12,MATCH($A14,$R$8:$R$12,1)+1)-INDEX($R$8:$R$12,MATCH($A14,$R$8:$R$12,1)))) -> 56.6 | P14: =IF($B$5="Low",N14,IF($B$5="High",O14,B14)) -> 46.896
A15: 2033 | B15: =IF($A15>=$R$12,S$12,INDEX(S$8:S$12,MATCH($A15,$R$8:$R$12,1))+(INDEX(S$8:S$12,MATCH($A15,$R$8:$R$12,1)+1)-INDEX(S$8:S$12,MATCH($A15,$R$8:$R$12,1)))*($A15-INDEX($R$8:$R$12,MATCH($A15,$R$8:$R$12,1)))/(INDEX($R$8:$R$12,MATCH($A15,$R$8:$R$12,1)+1)-INDEX($R$8:$R$12,MATCH($A15,$R$8:$R$12,1)))) -> 46.009 | C15: =Inputs!$B$79 -> 0.5 | D15: =Inputs!$B$80 -> 0.6 | E15: =Inputs!$B$81 -> 0.7 | F15: =IF($B$3="Low",C15,IF($B$3="High",E15,D15)) -> 0.6 | G15: =P15*F15*L15 -> 31.709927 | H15: =Inputs!B40*M15 -> 50 | I15: =J15*H15+(1-J15)*G15 -> 50 | J15: =IF(AND($B$4="Yes",K15=1),Inputs!$B$43,0) -> 1 | K15: =IF(AND(A15>=Inputs!$B$9,A15<Inputs!$B$9+Inputs!$B$44),1,0) -> 1 | L15: =(1+Inputs!$B$63)^(A15-$A$8) -> 1.1486857 | M15: =IF(Inputs!$B$64="Yes",L15,1) -> 1 | N15: =IF($A15>=$R$12,T$12,INDEX(T$8:T$12,MATCH($A15,$R$8:$R$12,1))+(INDEX(T$8:T$12,MATCH($A15,$R$8:$R$12,1)+1)-INDEX(T$8:T$12,MATCH($A15,$R$8:$R$12,1)))*($A15-INDEX($R$8:$R$12,MATCH($A15,$R$8:$R$12,1)))/(INDEX($R$8:$R$12,MATCH($A15,$R$8:$R$12,1)+1)-INDEX($R$8:$R$12,MATCH($A15,$R$8:$R$12,1)))) -> 34.07 | O15: =IF($A15>=$R$12,U$12,INDEX(U$8:U$12,MATCH($A15,$R$8:$R$12,1))+(INDEX(U$8:U$12,MATCH($A15,$R$8:$R$12,1)+1)-INDEX(U$8:U$12,MATCH($A15,$R$8:$R$12,1)))*($A15-INDEX($R$8:$R$12,MATCH($A15,$R$8:$R$12,1)))/(INDEX($R$8:$R$12,MATCH($A15,$R$8:$R$12,1)+1)-INDEX($R$8:$R$12,MATCH($A15,$R$8:$R$12,1)))) -> 56.6 | P15: =IF($B$5="Low",N15,IF($B$5="High",O15,B15)) -> 46.009
A16: 2034 | B16: =IF($A16>=$R$12,S$12,INDEX(S$8:S$12,MATCH($A16,$R$8:$R$12,1))+(INDEX(S$8:S$12,MATCH($A16,$R$8:$R$12,1)+1)-INDEX(S$8:S$12,MATCH($A16,$R$8:$R$12,1)))*($A16-INDEX($R$8:$R$12,MATCH($A16,$R$8:$R$12,1)))/(INDEX($R$8:$R$12,MATCH($A16,$R$8:$R$12,1)+1)-INDEX($R$8:$R$12,MATCH($A16,$R$8:$R$12,1)))) -> 45.122 | C16: =Inputs!$B$79 -> 0.5 | D16: =Inputs!$B$80 -> 0.6 | E16: =Inputs!$B$81 -> 0.7 | F16: =IF($B$3="Low",C16,IF($B$3="High",E16,D16)) -> 0.6 | G16: =P16*F16*L16 -> 31.720569 | H16: =Inputs!B40*M16 -> 50 | I16: =J16*H16+(1-J16)*G16 -> 50 | J16: =IF(AND($B$4="Yes",K16=1),Inputs!$B$43,0) -> 1 | K16: =IF(AND(A16>=Inputs!$B$9,A16<Inputs!$B$9+Inputs!$B$44),1,0) -> 1 | L16: =(1+Inputs!$B$63)^(A16-$A$8) -> 1.1716594 | M16: =IF(Inputs!$B$64="Yes",L16,1) -> 1 | N16: =IF($A16>=$R$12,T$12,INDEX(T$8:T$12,MATCH($A16,$R$8:$R$12,1))+(INDEX(T$8:T$12,MATCH($A16,$R$8:$R$12,1)+1)-INDEX(T$8:T$12,MATCH($A16,$R$8:$R$12,1)))*($A16-INDEX($R$8:$R$12,MATCH($A16,$R$8:$R$12,1)))/(INDEX($R$8:$R$12,MATCH($A16,$R$8:$R$12,1)+1)-INDEX($R$8:$R$12,MATCH($A16,$R$8:$R$12,1)))) -> 33.86 | O16: =IF($A16>=$R$12,U$12,INDEX(U$8:U$12,MATCH($A16,$R$8:$R$12,1))+(INDEX(U$8:U$12,MATCH($A16,$R$8:$R$12,1)+1)-INDEX(U$8:U$12,MATCH($A16,$R$8:$R$12,1)))*($A16-INDEX($R$8:$R$12,MATCH($A16,$R$8:$R$12,1)))/(INDEX($R$8:$R$12,MATCH($A16,$R$8:$R$12,1)+1)-INDEX($R$8:$R$12,MATCH($A16,$R$8:$R$12,1)))) -> 56.6 | P16: =IF($B$5="Low",N16,IF($B$5="High",O16,B16)) -> 45.122
A17: 2035 | B17: =IF($A17>=$R$12,S$12,INDEX(S$8:S$12,MATCH($A17,$R$8:$R$12,1))+(INDEX(S$8:S$12,MATCH($A17,$R$8:$R$12,1)+1)-INDEX(S$8:S$12,MATCH($A17,$R$8:$R$12,1)))*($A17-INDEX($R$8:$R$12,MATCH($A17,$R$8:$R$12,1)))/(INDEX($R$8:$R$12,MATCH($A17,$R$8:$R$12,1)+1)-INDEX($R$8:$R$12,MATCH($A17,$R$8:$R$12,1)))) -> 44.235 | C17: =Inputs!$B$79 -> 0.5 | D17: =Inputs!$B$80 -> 0.6 | E17: =Inputs!$B$81 -> 0.7 | F17: =IF($B$3="Low",C17,IF($B$3="High",E17,D17)) -> 0.6 | G17: =P17*F17*L17 -> 31.718952 | H17: =Inputs!B40*M17 -> 50 | I17: =J17*H17+(1-J17)*G17 -> 50 | J17: =IF(AND($B$4="Yes",K17=1),Inputs!$B$43,0) -> 1 | K17: =IF(AND(A17>=Inputs!$B$9,A17<Inputs!$B$9+Inputs!$B$44),1,0) -> 1 | L17: =(1+Inputs!$B$63)^(A17-$A$8) -> 1.1950926 | M17: =IF(Inputs!$B$64="Yes",L17,1) -> 1 | N17: =IF($A17>=$R$12,T$12,INDEX(T$8:T$12,MATCH($A17,$R$8:$R$12,1))+(INDEX(T$8:T$12,MATCH($A17,$R$8:$R$12,1)+1)-INDEX(T$8:T$12,MATCH($A17,$R$8:$R$12,1)))*($A17-INDEX($R$8:$R$12,MATCH($A17,$R$8:$R$12,1)))/(INDEX($R$8:$R$12,MATCH($A17,$R$8:$R$12,1)+1)-INDEX($R$8:$R$12,MATCH($A17,$R$8:$R$12,1)))) -> 33.65 | O17: =IF($A17>=$R$12,U$12,INDEX(U$8:U$12,MATCH($A17,$R$8:$R$12,1))+(INDEX(U$8:U$12,MATCH($A17,$R$8:$R$12,1)+1)-INDEX(U$8:U$12,MATCH($A17,$R$8:$R$12,1)))*($A17-INDEX($R$8:$R$12,MATCH($A17,$R$8:$R$12,1)))/(INDEX($R$8:$R$12,MATCH($A17,$R$8:$R$12,1)+1)-INDEX($R$8:$R$12,MATCH($A17,$R$8:$R$12,1)))) -> 56.6 | P17: =IF($B$5="Low",N17,IF($B$5="High",O17,B17)) -> 44.235
A18: 2036 | B18: =IF($A18>=$R$12,S$12,INDEX(S$8:S$12,MATCH($A18,$R$8:$R$12,1))+(INDEX(S$8:S$12,MATCH($A18,$R$8:$R$12,1)+1)-INDEX(S$8:S$12,MATCH($A18,$R$8:$R$12,1)))*($A18-INDEX($R$8:$R$12,MATCH($A18,$R$8:$R$12,1)))/(INDEX($R$8:$R$12,MATCH($A18,$R$8:$R$12,1)+1)-INDEX($R$8:$R$12,MATCH($A18,$R$8:$R$12,1)))) -> 43.348 | C18: =Inputs!$B$79 -> 0.5 | D18: =Inputs!$B$80 -> 0.6 | E18: =Inputs!$B$81 -> 0.7 | F18: =IF($B$3="Low",C18,IF($B$3="High",E18,D18)) -> 0.6 | G18: =P18*F18*L18 -> 31.704582 | H18: =Inputs!B40*M18 -> 50 | I18: =J18*H18+(1-J18)*G18 -> 50 | J18: =IF(AND($B$4="Yes",K18=1),Inputs!$B$43,0) -> 1 | K18: =IF(AND(A18>=Inputs!$B$9,A18<Inputs!$B$9+Inputs!$B$44),1,0) -> 1 | L18: =(1+Inputs!$B$63)^(A18-$A$8) -> 1.2189944 | M18: =IF(Inputs!$B$64="Yes",L18,1) -> 1 | N18: =IF($A18>=$R$12,T$12,INDEX(T$8:T$12,MATCH($A18,$R$8:$R$12,1))+(INDEX(T$8:T$12,MATCH($A18,$R$8:$R$12,1)+1)-INDEX(T$8:T$12,MATCH($A18,$R$8:$R$12,1)))*($A18-INDEX($R$8:$R$12,MATCH($A18,$R$8:$R$12,1)))/(INDEX($R$8:$R$12,MATCH($A18,$R$8:$R$12,1)+1)-INDEX($R$8:$R$12,MATCH($A18,$R$8:$R$12,1)))) -> 33.44 | O18: =IF($A18>=$R$12,U$12,INDEX(U$8:U$12,MATCH($A18,$R$8:$R$12,1))+(INDEX(U$8:U$12,MATCH($A18,$R$8:$R$12,1)+1)-INDEX(U$8:U$12,MATCH($A18,$R$8:$R$12,1)))*($A18-INDEX($R$8:$R$12,MATCH($A18,$R$8:$R$12,1)))/(INDEX($R$8:$R$12,MATCH($A18,$R$8:$R$12,1)+1)-INDEX($R$8:$R$12,MATCH($A18,$R$8:$R$12,1)))) -> 56.6 | P18: =IF($B$5="Low",N18,IF($B$5="High",O18,B18)) -> 43.348
A19: 2037 | B19: =IF($A19>=$R$12,S$12,INDEX(S$8:S$12,MATCH($A19,$R$8:$R$12,1))+(INDEX(S$8:S$12,MATCH($A19,$R$8:$R$12,1)+1)-INDEX(S$8:S$12,MATCH($A19,$R$8:$R$12,1)))*($A19-INDEX($R$8:$R$12,MATCH($A19,$R$8:$R$12,1)))/(INDEX($R$8:$R$12,MATCH($A19,$R$8:$R$12,1)+1)-INDEX($R$8:$R$12,MATCH($A19,$R$8:$R$12,1)))) -> 42.461 | C19: =Inputs!$B$79 -> 0.5 | D19: =Inputs!$B$80 -> 0.6 | E19: =Inputs!$B$81 -> 0.7 | F19: =IF($B$3="Low",C19,IF($B$3="High",E19,D19)) -> 0.6 | G19: =P19*F19*L19 -> 31.67695 | H19: =Inputs!B40*M19 -> 50 | I19: =J19*H19+(1-J19)*G19 -> 50 | J19: =IF(AND($B$4="Yes",K19=1),Inputs!$B$43,0) -> 1 | K19: =IF(AND(A19>=Inputs!$B$9,A19<Inputs!$B$9+Inputs!$B$44),1,0) -> 1 | L19: =(1+Inputs!$B$63)^(A19-$A$8) -> 1.2433743 | M19: =IF(Inputs!$B$64="Yes",L19,1) -> 1 | N19: =IF($A19>=$R$12,T$12,INDEX(T$8:T$12,MATCH($A19,$R$8:$R$12,1))+(INDEX(T$8:T$12,MATCH($A19,$R$8:$R$12,1)+1)-INDEX(T$8:T$12,MATCH($A19,$R$8:$R$12,1)))*($A19-INDEX($R$8:$R$12,MATCH($A19,$R$8:$R$12,1)))/(INDEX($R$8:$R$12,MATCH($A19,$R$8:$R$12,1)+1)-INDEX($R$8:$R$12,MATCH($A19,$R$8:$R$12,1)))) -> 33.23 | O19: =IF($A19>=$R$12,U$12,INDEX(U$8:U$12,MATCH($A19,$R$8:$R$12,1))+(INDEX(U$8:U$12,MATCH($A19,$R$8:$R$12,1)+1)-INDEX(U$8:U$12,MATCH($A19,$R$8:$R$12,1)))*($A19-INDEX($R$8:$R$12,MATCH($A19,$R$8:$R$12,1)))/(INDEX($R$8:$R$12,MATCH($A19,$R$8:$R$12,1)+1)-INDEX($R$8:$R$12,MATCH($A19,$R$8:$R$12,1)))) -> 56.6 | P19: =IF($B$5="Low",N19,IF($B$5="High",O19,B19)) -> 42.461
A20: 2038 | B20: =IF($A20>=$R$12,S$12,INDEX(S$8:S$12,MATCH($A20,$R$8:$R$12,1))+(INDEX(S$8:S$12,MATCH($A20,$R$8:$R$12,1)+1)-INDEX(S$8:S$12,MATCH($A20,$R$8:$R$12,1)))*($A20-INDEX($R$8:$R$12,MATCH($A20,$R$8:$R$12,1)))/(INDEX($R$8:$R$12,MATCH($A20,$R$8:$R$12,1)+1)-INDEX($R$8:$R$12,MATCH($A20,$R$8:$R$12,1)))) -> 41.574 | C20: =Inputs!$B$79 -> 0.5 | D20: =Inputs!$B$80 -> 0.6 | E20: =Inputs!$B$81 -> 0.7 | F20: =IF($B$3="Low",C20,IF($B$3="High",E20,D20)) -> 0.6 | G20: =P20*F20*L20 -> 31.635531 | H20: =Inputs!B40*M20 -> 50 | I20: =J20*H20+(1-J20)*G20 -> 50 | J20: =IF(AND($B$4="Yes",K20=1),Inputs!$B$43,0) -> 1 | K20: =IF(AND(A20>=Inputs!$B$9,A20<Inputs!$B$9+Inputs!$B$44),1,0) -> 1 | L20: =(1+Inputs!$B$63)^(A20-$A$8) -> 1.2682418 | M20: =IF(Inputs!$B$64="Yes",L20,1) -> 1 | N20: =IF($A20>=$R$12,T$12,INDEX(T$8:T$12,MATCH($A20,$R$8:$R$12,1))+(INDEX(T$8:T$12,MATCH($A20,$R$8:$R$12,1)+1)-INDEX(T$8:T$12,MATCH($A20,$R$8:$R$12,1)))*($A20-INDEX($R$8:$R$12,MATCH($A20,$R$8:$R$12,1)))/(INDEX($R$8:$R$12,MATCH($A20,$R$8:$R$12,1)+1)-INDEX($R$8:$R$12,MATCH($A20,$R$8:$R$12,1)))) -> 33.02 | O20: =IF($A20>=$R$12,U$12,INDEX(U$8:U$12,MATCH($A20,$R$8:$R$12,1))+(INDEX(U$8:U$12,MATCH($A20,$R$8:$R$12,1)+1)-INDEX(U$8:U$12,MATCH($A20,$R$8:$R$12,1)))*($A20-INDEX($R$8:$R$12,MATCH($A20,$R$8:$R$12,1)))/(INDEX($R$8:$R$12,MATCH($A20,$R$8:$R$12,1)+1)-INDEX($R$8:$R$12,MATCH($A20,$R$8:$R$12,1)))) -> 56.6 | P20: =IF($B$5="Low",N20,IF($B$5="High",O20,B20)) -> 41.574
A21: 2039 | B21: =IF($A21>=$R$12,S$12,INDEX(S$8:S$12,MATCH($A21,$R$8:$R$12,1))+(INDEX(S$8:S$12,MATCH($A21,$R$8:$R$12,1)+1)-INDEX(S$8:S$12,MATCH($A21,$R$8:$R$12,1)))*($A21-INDEX($R$8:$R$12,MATCH($A21,$R$8:$R$12,1)))/(INDEX($R$8:$R$12,MATCH($A21,$R$8:$R$12,1)+1)-INDEX($R$8:$R$12,MATCH($A21,$R$8:$R$12,1)))) -> 40.687 | C21: =Inputs!$B$79 -> 0.5 | D21: =Inputs!$B$80 -> 0.6 | E21: =Inputs!$B$81 -> 0.7 | F21: =IF($B$3="Low",C21,IF($B$3="High",E21,D21)) -> 0.6 | G21: =P21*F21*L21 -> 31.579784 | H21: =Inputs!B40*M21 -> 50 | I21: =J21*H21+(1-J21)*G21 -> 50 | J21: =IF(AND($B$4="Yes",K21=1),Inputs!$B$43,0) -> 1 | K21: =IF(AND(A21>=Inputs!$B$9,A21<Inputs!$B$9+Inputs!$B$44),1,0) -> 1 | L21: =(1+Inputs!$B$63)^(A21-$A$8) -> 1.2936066 | M21: =IF(Inputs!$B$64="Yes",L21,1) -> 1 | N21: =IF($A21>=$R$12,T$12,INDEX(T$8:T$12,MATCH($A21,$R$8:$R$12,1))+(INDEX(T$8:T$12,MATCH($A21,$R$8:$R$12,1)+1)-INDEX(T$8:T$12,MATCH($A21,$R$8:$R$12,1)))*($A21-INDEX($R$8:$R$12,MATCH($A21,$R$8:$R$12,1)))/(INDEX($R$8:$R$12,MATCH($A21,$R$8:$R$12,1)+1)-INDEX($R$8:$R$12,MATCH($A21,$R$8:$R$12,1)))) -> 32.81 | O21: =IF($A21>=$R$12,U$12,INDEX(U$8:U$12,MATCH($A21,$R$8:$R$12,1))+(INDEX(U$8:U$12,MATCH($A21,$R$8:$R$12,1)+1)-INDEX(U$8:U$12,MATCH($A21,$R$8:$R$12,1)))*($A21-INDEX($R$8:$R$12,MATCH($A21,$R$8:$R$12,1)))/(INDEX($R$8:$R$12,MATCH($A21,$R$8:$R$12,1)+1)-INDEX($R$8:$R$12,MATCH($A21,$R$8:$R$12,1)))) -> 56.6 | P21: =IF($B$5="Low",N21,IF($B$5="High",O21,B21)) -> 40.687
A22: 2040 | B22: =IF($A22>=$R$12,S$12,INDEX(S$8:S$12,MATCH($A22,$R$8:$R$12,1))+(INDEX(S$8:S$12,MATCH($A22,$R$8:$R$12,1)+1)-INDEX(S$8:S$12,MATCH($A22,$R$8:$R$12,1)))*($A22-INDEX($R$8:$R$12,MATCH($A22,$R$8:$R$12,1)))/(INDEX($R$8:$R$12,MATCH($A22,$R$8:$R$12,1)+1)-INDEX($R$8:$R$12,MATCH($A22,$R$8:$R$12,1)))) -> 39.8 | C22: =Inputs!$B$79 -> 0.5 | D22: =Inputs!$B$80 -> 0.6 | E22: =Inputs!$B$81 -> 0.7 | F22: =IF($B$3="Low",C22,IF($B$3="High",E22,D22)) -> 0.6 | G22: =P22*F22*L22 -> 31.509153 | H22: =Inputs!B40*M22 -> 50 | I22: =J22*H22+(1-J22)*G22 -> 50 | J22: =IF(AND($B$4="Yes",K22=1),Inputs!$B$43,0) -> 1 | K22: =IF(AND(A22>=Inputs!$B$9,A22<Inputs!$B$9+Inputs!$B$44),1,0) -> 1 | L22: =(1+Inputs!$B$63)^(A22-$A$8) -> 1.3194788 | M22: =IF(Inputs!$B$64="Yes",L22,1) -> 1 | N22: =IF($A22>=$R$12,T$12,INDEX(T$8:T$12,MATCH($A22,$R$8:$R$12,1))+(INDEX(T$8:T$12,MATCH($A22,$R$8:$R$12,1)+1)-INDEX(T$8:T$12,MATCH($A22,$R$8:$R$12,1)))*($A22-INDEX($R$8:$R$12,MATCH($A22,$R$8:$R$12,1)))/(INDEX($R$8:$R$12,MATCH($A22,$R$8:$R$12,1)+1)-INDEX($R$8:$R$12,MATCH($A22,$R$8:$R$12,1)))) -> 32.6 | O22: =IF($A22>=$R$12,U$12,INDEX(U$8:U$12,MATCH($A22,$R$8:$R$12,1))+(INDEX(U$8:U$12,MATCH($A22,$R$8:$R$12,1)+1)-INDEX(U$8:U$12,MATCH($A22,$R$8:$R$12,1)))*($A22-INDEX($R$8:$R$12,MATCH($A22,$R$8:$R$12,1)))/(INDEX($R$8:$R$12,MATCH($A22,$R$8:$R$12,1)+1)-INDEX($R$8:$R$12,MATCH($A22,$R$8:$R$12,1)))) -> 56.6 | P22: =IF($B$5="Low",N22,IF($B$5="High",O22,B22)) -> 39.8
A23: 2041 | B23: =IF($A23>=$R$12,S$12,INDEX(S$8:S$12,MATCH($A23,$R$8:$R$12,1))+(INDEX(S$8:S$12,MATCH($A23,$R$8:$R$12,1)+1)-INDEX(S$8:S$12,MATCH($A23,$R$8:$R$12,1)))*($A23-INDEX($R$8:$R$12,MATCH($A23,$R$8:$R$12,1)))/(INDEX($R$8:$R$12,MATCH($A23,$R$8:$R$12,1)+1)-INDEX($R$8:$R$12,MATCH($A23,$R$8:$R$12,1)))) -> 40.38 | C23: =Inputs!$B$79 -> 0.5 | D23: =Inputs!$B$80 -> 0.6 | E23: =Inputs!$B$81 -> 0.7 | F23: =IF($B$3="Low",C23,IF($B$3="High",E23,D23)) -> 0.6 | G23: =P23*F23*L23 -> 32.607698 | H23: =Inputs!B40*M23 -> 50 | I23: =J23*H23+(1-J23)*G23 -> 50 | J23: =IF(AND($B$4="Yes",K23=1),Inputs!$B$43,0) -> 1 | K23: =IF(AND(A23>=Inputs!$B$9,A23<Inputs!$B$9+Inputs!$B$44),1,0) -> 1 | L23: =(1+Inputs!$B$63)^(A23-$A$8) -> 1.3458683 | M23: =IF(Inputs!$B$64="Yes",L23,1) -> 1 | N23: =IF($A23>=$R$12,T$12,INDEX(T$8:T$12,MATCH($A23,$R$8:$R$12,1))+(INDEX(T$8:T$12,MATCH($A23,$R$8:$R$12,1)+1)-INDEX(T$8:T$12,MATCH($A23,$R$8:$R$12,1)))*($A23-INDEX($R$8:$R$12,MATCH($A23,$R$8:$R$12,1)))/(INDEX($R$8:$R$12,MATCH($A23,$R$8:$R$12,1)+1)-INDEX($R$8:$R$12,MATCH($A23,$R$8:$R$12,1)))) -> 33.08 | O23: =IF($A23>=$R$12,U$12,INDEX(U$8:U$12,MATCH($A23,$R$8:$R$12,1))+(INDEX(U$8:U$12,MATCH($A23,$R$8:$R$12,1)+1)-INDEX(U$8:U$12,MATCH($A23,$R$8:$R$12,1)))*($A23-INDEX($R$8:$R$12,MATCH($A23,$R$8:$R$12,1)))/(INDEX($R$8:$R$12,MATCH($A23,$R$8:$R$12,1)+1)-INDEX($R$8:$R$12,MATCH($A23,$R$8:$R$12,1)))) -> 56.6 | P23: =IF($B$5="Low",N23,IF($B$5="High",O23,B23)) -> 40.38
A24: 2042 | B24: =IF($A24>=$R$12,S$12,INDEX(S$8:S$12,MATCH($A24,$R$8:$R$12,1))+(INDEX(S$8:S$12,MATCH($A24,$R$8:$R$12,1)+1)-INDEX(S$8:S$12,MATCH($A24,$R$8:$R$12,1)))*($A24-INDEX($R$8:$R$12,MATCH($A24,$R$8:$R$12,1)))/(INDEX($R$8:$R$12,MATCH($A24,$R$8:$R$12,1)+1)-INDEX($R$8:$R$12,MATCH($A24,$R$8:$R$12,1)))) -> 40.96 | C24: =Inputs!$B$79 -> 0.5 | D24: =Inputs!$B$80 -> 0.6 | E24: =Inputs!$B$81 -> 0.7 | F24: =IF($B$3="Low",C24,IF($B$3="High",E24,D24)) -> 0.6 | G24: =P24*F24*L24 -> 33.737581 | H24: =Inputs!B40*M24 -> 50 | I24: =J24*H24+(1-J24)*G24 -> 50 | J24: =IF(AND($B$4="Yes",K24=1),Inputs!$B$43,0) -> 1 | K24: =IF(AND(A24>=Inputs!$B$9,A24<Inputs!$B$9+Inputs!$B$44),1,0) -> 1 | L24: =(1+Inputs!$B$63)^(A24-$A$8) -> 1.3727857 | M24: =IF(Inputs!$B$64="Yes",L24,1) -> 1 | N24: =IF($A24>=$R$12,T$12,INDEX(T$8:T$12,MATCH($A24,$R$8:$R$12,1))+(INDEX(T$8:T$12,MATCH($A24,$R$8:$R$12,1)+1)-INDEX(T$8:T$12,MATCH($A24,$R$8:$R$12,1)))*($A24-INDEX($R$8:$R$12,MATCH($A24,$R$8:$R$12,1)))/(INDEX($R$8:$R$12,MATCH($A24,$R$8:$R$12,1)+1)-INDEX($R$8:$R$12,MATCH($A24,$R$8:$R$12,1)))) -> 33.56 | O24: =IF($A24>=$R$12,U$12,INDEX(U$8:U$12,MATCH($A24,$R$8:$R$12,1))+(INDEX(U$8:U$12,MATCH($A24,$R$8:$R$12,1)+1)-INDEX(U$8:U$12,MATCH($A24,$R$8:$R$12,1)))*($A24-INDEX($R$8:$R$12,MATCH($A24,$R$8:$R$12,1)))/(INDEX($R$8:$R$12,MATCH($A24,$R$8:$R$12,1)+1)-INDEX($R$8:$R$12,MATCH($A24,$R$8:$R$12,1)))) -> 56.6 | P24: =IF($B$5="Low",N24,IF($B$5="High",O24,B24)) -> 40.96
A25: 2043 | B25: =IF($A25>=$R$12,S$12,INDEX(S$8:S$12,MATCH($A25,$R$8:$R$12,1))+(INDEX(S$8:S$12,MATCH($A25,$R$8:$R$12,1)+1)-INDEX(S$8:S$12,MATCH($A25,$R$8:$R$12,1)))*($A25-INDEX($R$8:$R$12,MATCH($A25,$R$8:$R$12,1)))/(INDEX($R$8:$R$12,MATCH($A25,$R$8:$R$12,1)+1)-INDEX($R$8:$R$12,MATCH($A25,$R$8:$R$12,1)))) -> 41.54 | C25: =Inputs!$B$79 -> 0.5 | D25: =Inputs!$B$80 -> 0.6 | E25: =Inputs!$B$81 -> 0.7 | F25: =IF($B$3="Low",C25,IF($B$3="High",E25,D25)) -> 0.6 | G25: =P25*F25*L25 -> 34.899617 | H25: =Inputs!B40*M25 -> 50 | I25: =J25*H25+(1-J25)*G25 -> 34.899617 | J25: =IF(AND($B$4="Yes",K25=1),Inputs!$B$43,0) -> 0 | K25: =IF(AND(A25>=Inputs!$B$9,A25<Inputs!$B$9+Inputs!$B$44),1,0) -> 0 | L25: =(1+Inputs!$B$63)^(A25-$A$8) -> 1.4002414 | M25: =IF(Inputs!$B$64="Yes",L25,1) -> 1 | N25: =IF($A25>=$R$12,T$12,INDEX(T$8:T$12,MATCH($A25,$R$8:$R$12,1))+(INDEX(T$8:T$12,MATCH($A25,$R$8:$R$12,1)+1)-INDEX(T$8:T$12,MATCH($A25,$R$8:$R$12,1)))*($A25-INDEX($R$8:$R$12,MATCH($A25,$R$8:$R$12,1)))/(INDEX($R$8:$R$12,MATCH($A25,$R$8:$R$12,1)+1)-INDEX($R$8:$R$12,MATCH($A25,$R$8:$R$12,1)))) -> 34.04 | O25: =IF($A25>=$R$12,U$12,INDEX(U$8:U$12,MATCH($A25,$R$8:$R$12,1))+(INDEX(U$8:U$12,MATCH($A25,$R$8:$R$12,1)+1)-INDEX(U$8:U$12,MATCH($A25,$R$8:$R$12,1)))*($A25-INDEX($R$8:$R$12,MATCH($A25,$R$8:$R$12,1)))/(INDEX($R$8:$R$12,MATCH($A25,$R$8:$R$12,1)+1)-INDEX($R$8:$R$12,MATCH($A25,$R$8:$R$12,1)))) -> 56.6 | P25: =IF($B$5="Low",N25,IF($B$5="High",O25,B25)) -> 41.54
A26: 2044 | B26: =IF($A26>=$R$12,S$12,INDEX(S$8:S$12,MATCH($A26,$R$8:$R$12,1))+(INDEX(S$8:S$12,MATCH($A26,$R$8:$R$12,1)+1)-INDEX(S$8:S$12,MATCH($A26,$R$8:$R$12,1)))*($A26-INDEX($R$8:$R$12,MATCH($A26,$R$8:$R$12,1)))/(INDEX($R$8:$R$12,MATCH($A26,$R$8:$R$12,1)+1)-INDEX($R$8:$R$12,MATCH($A26,$R$8:$R$12,1)))) -> 42.12 | C26: =Inputs!$B$79 -> 0.5 | D26: =Inputs!$B$80 -> 0.6 | E26: =Inputs!$B$81 -> 0.7 | F26: =IF($B$3="Low",C26,IF($B$3="High",E26,D26)) -> 0.6 | G26: =P26*F26*L26 -> 36.094639 | H26: =Inputs!B40*M26 -> 50 | I26: =J26*H26+(1-J26)*G26 -> 36.094639 | J26: =IF(AND($B$4="Yes",K26=1),Inputs!$B$43,0) -> 0 | K26: =IF(AND(A26>=Inputs!$B$9,A26<Inputs!$B$9+Inputs!$B$44),1,0) -> 0 | L26: =(1+Inputs!$B$63)^(A26-$A$8) -> 1.4282462 | M26: =IF(Inputs!$B$64="Yes",L26,1) -> 1 | N26: =IF($A26>=$R$12,T$12,INDEX(T$8:T$12,MATCH($A26,$R$8:$R$12,1))+(INDEX(T$8:T$12,MATCH($A26,$R$8:$R$12,1)+1)-INDEX(T$8:T$12,MATCH($A26,$R$8:$R$12,1)))*($A26-INDEX($R$8:$R$12,MATCH($A26,$R$8:$R$12,1)))/(INDEX($R$8:$R$12,MATCH($A26,$R$8:$R$12,1)+1)-INDEX($R$8:$R$12,MATCH($A26,$R$8:$R$12,1)))) -> 34.52 | O26: =IF($A26>=$R$12,U$12,INDEX(U$8:U$12,MATCH($A26,$R$8:$R$12,1))+(INDEX(U$8:U$12,MATCH($A26,$R$8:$R$12,1)+1)-INDEX(U$8:U$12,MATCH($A26,$R$8:$R$12,1)))*($A26-INDEX($R$8:$R$12,MATCH($A26,$R$8:$R$12,1)))/(INDEX($R$8:$R$12,MATCH($A26,$R$8:$R$12,1)+1)-INDEX($R$8:$R$12,MATCH($A26,$R$8:$R$12,1)))) -> 56.6 | P26: =IF($B$5="Low",N26,IF($B$5="High",O26,B26)) -> 42.12
A27: 2045 | B27: =IF($A27>=$R$12,S$12,INDEX(S$8:S$12,MATCH($A27,$R$8:$R$12,1))+(INDEX(S$8:S$12,MATCH($A27,$R$8:$R$12,1)+1)-INDEX(S$8:S$12,MATCH($A27,$R$8:$R$12,1)))*($A27-INDEX($R$8:$R$12,MATCH($A27,$R$8:$R$12,1)))/(INDEX($R$8:$R$12,MATCH($A27,$R$8:$R$12,1)+1)-INDEX($R$8:$R$12,MATCH($A27,$R$8:$R$12,1)))) -> 42.7 | C27: =Inputs!$B$79 -> 0.5 | D27: =Inputs!$B$80 -> 0.6 | E27: =Inputs!$B$81 -> 0.7 | F27: =IF($B$3="Low",C27,IF($B$3="High",E27,D27)) -> 0.6 | G27: =P27*F27*L27 -> 37.323502 | H27: =Inputs!B40*M27 -> 50 | I27: =J27*H27+(1-J27)*G27 -> 37.323502 | J27: =IF(AND($B$4="Yes",K27=1),Inputs!$B$43,0) -> 0 | K27: =IF(AND(A27>=Inputs!$B$9,A27<Inputs!$B$9+Inputs!$B$44),1,0) -> 0 | L27: =(1+Inputs!$B$63)^(A27-$A$8) -> 1.4568112 | M27: =IF(Inputs!$B$64="Yes",L27,1) -> 1 | N27: =IF($A27>=$R$12,T$12,INDEX(T$8:T$12,MATCH($A27,$R$8:$R$12,1))+(INDEX(T$8:T$12,MATCH($A27,$R$8:$R$12,1)+1)-INDEX(T$8:T$12,MATCH($A27,$R$8:$R$12,1)))*($A27-INDEX($R$8:$R$12,MATCH($A27,$R$8:$R$12,1)))/(INDEX($R$8:$R$12,MATCH($A27,$R$8:$R$12,1)+1)-INDEX($R$8:$R$12,MATCH($A27,$R$8:$R$12,1)))) -> 35 | O27: =IF($A27>=$R$12,U$12,INDEX(U$8:U$12,MATCH($A27,$R$8:$R$12,1))+(INDEX(U$8:U$12,MATCH($A27,$R$8:$R$12,1)+1)-INDEX(U$8:U$12,MATCH($A27,$R$8:$R$12,1)))*($A27-INDEX($R$8:$R$12,MATCH($A27,$R$8:$R$12,1)))/(INDEX($R$8:$R$12,MATCH($A27,$R$8:$R$12,1)+1)-INDEX($R$8:$R$12,MATCH($A27,$R$8:$R$12,1)))) -> 56.6 | P27: =IF($B$5="Low",N27,IF($B$5="High",O27,B27)) -> 42.7
A28: 2046 | B28: =IF($A28>=$R$12,S$12,INDEX(S$8:S$12,MATCH($A28,$R$8:$R$12,1))+(INDEX(S$8:S$12,MATCH($A28,$R$8:$R$12,1)+1)-INDEX(S$8:S$12,MATCH($A28,$R$8:$R$12,1)))*($A28-INDEX($R$8:$R$12,MATCH($A28,$R$8:$R$12,1)))/(INDEX($R$8:$R$12,MATCH($A28,$R$8:$R$12,1)+1)-INDEX($R$8:$R$12,MATCH($A28,$R$8:$R$12,1)))) -> 43.28 | C28: =Inputs!$B$79 -> 0.5 | D28: =Inputs!$B$80 -> 0.6 | E28: =Inputs!$B$81 -> 0.7 | F28: =IF($B$3="Low",C28,IF($B$3="High",E28,D28)) -> 0.6 | G28: =P28*F28*L28 -> 38.587082 | H28: =Inputs!B40*M28 -> 50 | I28: =J28*H28+(1-J28)*G28 -> 38.587082 | J28: =IF(AND($B$4="Yes",K28=1),Inputs!$B$43,0) -> 0 | K28: =IF(AND(A28>=Inputs!$B$9,A28<Inputs!$B$9+Inputs!$B$44),1,0) -> 0 | L28: =(1+Inputs!$B$63)^(A28-$A$8) -> 1.4859474 | M28: =IF(Inputs!$B$64="Yes",L28,1) -> 1 | N28: =IF($A28>=$R$12,T$12,INDEX(T$8:T$12,MATCH($A28,$R$8:$R$12,1))+(INDEX(T$8:T$12,MATCH($A28,$R$8:$R$12,1)+1)-INDEX(T$8:T$12,MATCH($A28,$R$8:$R$12,1)))*($A28-INDEX($R$8:$R$12,MATCH($A28,$R$8:$R$12,1)))/(INDEX($R$8:$R$12,MATCH($A28,$R$8:$R$12,1)+1)-INDEX($R$8:$R$12,MATCH($A28,$R$8:$R$12,1)))) -> 35.48 | O28: =IF($A28>=$R$12,U$12,INDEX(U$8:U$12,MATCH($A28,$R$8:$R$12,1))+(INDEX(U$8:U$12,MATCH($A28,$R$8:$R$12,1)+1)-INDEX(U$8:U$12,MATCH($A28,$R$8:$R$12,1)))*($A28-INDEX($R$8:$R$12,MATCH($A28,$R$8:$R$12,1)))/(INDEX($R$8:$R$12,MATCH($A28,$R$8:$R$12,1)+1)-INDEX($R$8:$R$12,MATCH($A28,$R$8:$R$12,1)))) -> 56.6 | P28: =IF($B$5="Low",N28,IF($B$5="High",O28,B28)) -> 43.28
A29: 2047 | B29: =IF($A29>=$R$12,S$12,INDEX(S$8:S$12,MATCH($A29,$R$8:$R$12,1))+(INDEX(S$8:S$12,MATCH($A29,$R$8:$R$12,1)+1)-INDEX(S$8:S$12,MATCH($A29,$R$8:$R$12,1)))*($A29-INDEX($R$8:$R$12,MATCH($A29,$R$8:$R$12,1)))/(INDEX($R$8:$R$12,MATCH($A29,$R$8:$R$12,1)+1)-INDEX($R$8:$R$12,MATCH($A29,$R$8:$R$12,1)))) -> 43.86 | C29: =Inputs!$B$79 -> 0.5 | D29: =Inputs!$B$80 -> 0.6 | E29: =Inputs!$B$81 -> 0.7 | F29: =IF($B$3="Low",C29,IF($B$3="High",E29,D29)) -> 0.6 | G29: =P29*F29*L29 -> 39.886276 | H29: =Inputs!B40*M29 -> 50 | I29: =J29*H29+(1-J29)*G29 -> 39.886276 | J29: =IF(AND($B$4="Yes",K29=1),Inputs!$B$43,0) -> 0 | K29: =IF(AND(A29>=Inputs!$B$9,A29<Inputs!$B$9+Inputs!$B$44),1,0) -> 0 | L29: =(1+Inputs!$B$63)^(A29-$A$8) -> 1.5156663 | M29: =IF(Inputs!$B$64="Yes",L29,1) -> 1 | N29: =IF($A29>=$R$12,T$12,INDEX(T$8:T$12,MATCH($A29,$R$8:$R$12,1))+(INDEX(T$8:T$12,MATCH($A29,$R$8:$R$12,1)+1)-INDEX(T$8:T$12,MATCH($A29,$R$8:$R$12,1)))*($A29-INDEX($R$8:$R$12,MATCH($A29,$R$8:$R$12,1)))/(INDEX($R$8:$R$12,MATCH($A29,$R$8:$R$12,1)+1)-INDEX($R$8:$R$12,MATCH($A29,$R$8:$R$12,1)))) -> 35.96 | O29: =IF($A29>=$R$12,U$12,INDEX(U$8:U$12,MATCH($A29,$R$8:$R$12,1))+(INDEX(U$8:U$12,MATCH($A29,$R$8:$R$12,1)+1)-INDEX(U$8:U$12,MATCH($A29,$R$8:$R$12,1)))*($A29-INDEX($R$8:$R$12,MATCH($A29,$R$8:$R$12,1)))/(INDEX($R$8:$R$12,MATCH($A29,$R$8:$R$12,1)+1)-INDEX($R$8:$R$12,MATCH($A29,$R$8:$R$12,1)))) -> 56.6 | P29: =IF($B$5="Low",N29,IF($B$5="High",O29,B29)) -> 43.86
A30: 2048 | B30: =IF($A30>=$R$12,S$12,INDEX(S$8:S$12,MATCH($A30,$R$8:$R$12,1))+(INDEX(S$8:S$12,MATCH($A30,$R$8:$R$12,1)+1)-INDEX(S$8:S$12,MATCH($A30,$R$8:$R$12,1)))*($A30-INDEX($R$8:$R$12,MATCH($A30,$R$8:$R$12,1)))/(INDEX($R$8:$R$12,MATCH($A30,$R$8:$R$12,1)+1)-INDEX($R$8:$R$12,MATCH($A30,$R$8:$R$12,1)))) -> 44.44 | C30: =Inputs!$B$79 -> 0.5 | D30: =Inputs!$B$80 -> 0.6 | E30: =Inputs!$B$81 -> 0.7 | F30: =IF($B$3="Low",C30,IF($B$3="High",E30,D30)) -> 0.6 | G30: =P30*F30*L30 -> 41.222002 | H30: =Inputs!B40*M30 -> 50 | I30: =J30*H30+(1-J30)*G30 -> 41.222002 | J30: =IF(AND($B$4="Yes",K30=1),Inputs!$B$43,0) -> 0 | K30: =IF(AND(A30>=Inputs!$B$9,A30<Inputs!$B$9+Inputs!$B$44),1,0) -> 0 | L30: =(1+Inputs!$B$63)^(A30-$A$8) -> 1.5459797 | M30: =IF(Inputs!$B$64="Yes",L30,1) -> 1 | N30: =IF($A30>=$R$12,T$12,INDEX(T$8:T$12,MATCH($A30,$R$8:$R$12,1))+(INDEX(T$8:T$12,MATCH($A30,$R$8:$R$12,1)+1)-INDEX(T$8:T$12,MATCH($A30,$R$8:$R$12,1)))*($A30-INDEX($R$8:$R$12,MATCH($A30,$R$8:$R$12,1)))/(INDEX($R$8:$R$12,MATCH($A30,$R$8:$R$12,1)+1)-INDEX($R$8:$R$12,MATCH($A30,$R$8:$R$12,1)))) -> 36.44 | O30: =IF($A30>=$R$12,U$12,INDEX(U$8:U$12,MATCH($A30,$R$8:$R$12,1))+(INDEX(U$8:U$12,MATCH($A30,$R$8:$R$12,1)+1)-INDEX(U$8:U$12,MATCH($A30,$R$8:$R$12,1)))*($A30-INDEX($R$8:$R$12,MATCH($A30,$R$8:$R$12,1)))/(INDEX($R$8:$R$12,MATCH($A30,$R$8:$R$12,1)+1)-INDEX($R$8:$R$12,MATCH($A30,$R$8:$R$12,1)))) -> 56.6 | P30: =IF($B$5="Low",N30,IF($B$5="High",O30,B30)) -> 44.44
A31: 2049 | B31: =IF($A31>=$R$12,S$12,INDEX(S$8:S$12,MATCH($A31,$R$8:$R$12,1))+(INDEX(S$8:S$12,MATCH($A31,$R$8:$R$12,1)+1)-INDEX(S$8:S$12,MATCH($A31,$R$8:$R$12,1)))*($A31-INDEX($R$8:$R$12,MATCH($A31,$R$8:$R$12,1)))/(INDEX($R$8:$R$12,MATCH($A31,$R$8:$R$12,1)+1)-INDEX($R$8:$R$12,MATCH($A31,$R$8:$R$12,1)))) -> 45.02 | C31: =Inputs!$B$79 -> 0.5 | D31: =Inputs!$B$80 -> 0.6 | E31: =Inputs!$B$81 -> 0.7 | F31: =IF($B$3="Low",C31,IF($B$3="High",E31,D31)) -> 0.6 | G31: =P31*F31*L31 -> 42.595203 | H31: =Inputs!B40*M31 -> 50 | I31: =J31*H31+(1-J31)*G31 -> 42.595203 | J31: =IF(AND($B$4="Yes",K31=1),Inputs!$B$43,0) -> 0 | K31: =IF(AND(A31>=Inputs!$B$9,A31<Inputs!$B$9+Inputs!$B$44),1,0) -> 0 | L31: =(1+Inputs!$B$63)^(A31-$A$8) -> 1.5768993 | M31: =IF(Inputs!$B$64="Yes",L31,1) -> 1 | N31: =IF($A31>=$R$12,T$12,INDEX(T$8:T$12,MATCH($A31,$R$8:$R$12,1))+(INDEX(T$8:T$12,MATCH($A31,$R$8:$R$12,1)+1)-INDEX(T$8:T$12,MATCH($A31,$R$8:$R$12,1)))*($A31-INDEX($R$8:$R$12,MATCH($A31,$R$8:$R$12,1)))/(INDEX($R$8:$R$12,MATCH($A31,$R$8:$R$12,1)+1)-INDEX($R$8:$R$12,MATCH($A31,$R$8:$R$12,1)))) -> 36.92 | O31: =IF($A31>=$R$12,U$12,INDEX(U$8:U$12,MATCH($A31,$R$8:$R$12,1))+(INDEX(U$8:U$12,MATCH($A31,$R$8:$R$12,1)+1)-INDEX(U$8:U$12,MATCH($A31,$R$8:$R$12,1)))*($A31-INDEX($R$8:$R$12,MATCH($A31,$R$8:$R$12,1)))/(INDEX($R$8:$R$12,MATCH($A31,$R$8:$R$12,1)+1)-INDEX($R$8:$R$12,MATCH($A31,$R$8:$R$12,1)))) -> 56.6 | P31: =IF($B$5="Low",N31,IF($B$5="High",O31,B31)) -> 45.02
A32: 2050 | B32: =IF($A32>=$R$12,S$12,INDEX(S$8:S$12,MATCH($A32,$R$8:$R$12,1))+(INDEX(S$8:S$12,MATCH($A32,$R$8:$R$12,1)+1)-INDEX(S$8:S$12,MATCH($A32,$R$8:$R$12,1)))*($A32-INDEX($R$8:$R$12,MATCH($A32,$R$8:$R$12,1)))/(INDEX($R$8:$R$12,MATCH($A32,$R$8:$R$12,1)+1)-INDEX($R$8:$R$12,MATCH($A32,$R$8:$R$12,1)))) -> 45.6 | C32: =Inputs!$B$79 -> 0.5 | D32: =Inputs!$B$80 -> 0.6 | E32: =Inputs!$B$81 -> 0.7 | F32: =IF($B$3="Low",C32,IF($B$3="High",E32,D32)) -> 0.6 | G32: =P32*F32*L32 -> 44.006843 | H32: =Inputs!B40*M32 -> 50 | I32: =J32*H32+(1-J32)*G32 -> 44.006843 | J32: =IF(AND($B$4="Yes",K32=1),Inputs!$B$43,0) -> 0 | K32: =IF(AND(A32>=Inputs!$B$9,A32<Inputs!$B$9+Inputs!$B$44),1,0) -> 0 | L32: =(1+Inputs!$B$63)^(A32-$A$8) -> 1.6084372 | M32: =IF(Inputs!$B$64="Yes",L32,1) -> 1 | N32: =IF($A32>=$R$12,T$12,INDEX(T$8:T$12,MATCH($A32,$R$8:$R$12,1))+(INDEX(T$8:T$12,MATCH($A32,$R$8:$R$12,1)+1)-INDEX(T$8:T$12,MATCH($A32,$R$8:$R$12,1)))*($A32-INDEX($R$8:$R$12,MATCH($A32,$R$8:$R$12,1)))/(INDEX($R$8:$R$12,MATCH($A32,$R$8:$R$12,1)+1)-INDEX($R$8:$R$12,MATCH($A32,$R$8:$R$12,1)))) -> 37.4 | O32: =IF($A32>=$R$12,U$12,INDEX(U$8:U$12,MATCH($A32,$R$8:$R$12,1))+(INDEX(U$8:U$12,MATCH($A32,$R$8:$R$12,1)+1)-INDEX(U$8:U$12,MATCH($A32,$R$8:$R$12,1)))*($A32-INDEX($R$8:$R$12,MATCH($A32,$R$8:$R$12,1)))/(INDEX($R$8:$R$12,MATCH($A32,$R$8:$R$12,1)+1)-INDEX($R$8:$R$12,MATCH($A32,$R$8:$R$12,1)))) -> 56.6 | P32: =IF($B$5="Low",N32,IF($B$5="High",O32,B32)) -> 45.6
A33: 2051 | B33: =IF($A33>=$R$12,S$12,INDEX(S$8:S$12,MATCH($A33,$R$8:$R$12,1))+(INDEX(S$8:S$12,MATCH($A33,$R$8:$R$12,1)+1)-INDEX(S$8:S$12,MATCH($A33,$R$8:$R$12,1)))*($A33-INDEX($R$8:$R$12,MATCH($A33,$R$8:$R$12,1)))/(INDEX($R$8:$R$12,MATCH($A33,$R$8:$R$12,1)+1)-INDEX($R$8:$R$12,MATCH($A33,$R$8:$R$12,1)))) -> 45.6 | C33: =Inputs!$B$79 -> 0.5 | D33: =Inputs!$B$80 -> 0.6 | E33: =Inputs!$B$81 -> 0.7 | F33: =IF($B$3="Low",C33,IF($B$3="High",E33,D33)) -> 0.6 | G33: =P33*F33*L33 -> 44.88698 | H33: =Inputs!B40*M33 -> 50 | I33: =J33*H33+(1-J33)*G33 -> 44.88698 | J33: =IF(AND($B$4="Yes",K33=1),Inputs!$B$43,0) -> 0 | K33: =IF(AND(A33>=Inputs!$B$9,A33<Inputs!$B$9+Inputs!$B$44),1,0) -> 0 | L33: =(1+Inputs!$B$63)^(A33-$A$8) -> 1.640606 | M33: =IF(Inputs!$B$64="Yes",L33,1) -> 1 | N33: =IF($A33>=$R$12,T$12,INDEX(T$8:T$12,MATCH($A33,$R$8:$R$12,1))+(INDEX(T$8:T$12,MATCH($A33,$R$8:$R$12,1)+1)-INDEX(T$8:T$12,MATCH($A33,$R$8:$R$12,1)))*($A33-INDEX($R$8:$R$12,MATCH($A33,$R$8:$R$12,1)))/(INDEX($R$8:$R$12,MATCH($A33,$R$8:$R$12,1)+1)-INDEX($R$8:$R$12,MATCH($A33,$R$8:$R$12,1)))) -> 37.4 | O33: =IF($A33>=$R$12,U$12,INDEX(U$8:U$12,MATCH($A33,$R$8:$R$12,1))+(INDEX(U$8:U$12,MATCH($A33,$R$8:$R$12,1)+1)-INDEX(U$8:U$12,MATCH($A33,$R$8:$R$12,1)))*($A33-INDEX($R$8:$R$12,MATCH($A33,$R$8:$R$12,1)))/(INDEX($R$8:$R$12,MATCH($A33,$R$8:$R$12,1)+1)-INDEX($R$8:$R$12,MATCH($A33,$R$8:$R$12,1)))) -> 56.6 | P33: =IF($B$5="Low",N33,IF($B$5="High",O33,B33)) -> 45.6
A34: 2052 | B34: =IF($A34>=$R$12,S$12,INDEX(S$8:S$12,MATCH($A34,$R$8:$R$12,1))+(INDEX(S$8:S$12,MATCH($A34,$R$8:$R$12,1)+1)-INDEX(S$8:S$12,MATCH($A34,$R$8:$R$12,1)))*($A34-INDEX($R$8:$R$12,MATCH($A34,$R$8:$R$12,1)))/(INDEX($R$8:$R$12,MATCH($A34,$R$8:$R$12,1)+1)-INDEX($R$8:$R$12,MATCH($A34,$R$8:$R$12,1)))) -> 45.6 | C34: =Inputs!$B$79 -> 0.5 | D34: =Inputs!$B$80 -> 0.6 | E34: =Inputs!$B$81 -> 0.7 | F34: =IF($B$3="Low",C34,IF($B$3="High",E34,D34)) -> 0.6 | G34: =P34*F34*L34 -> 45.78472 | H34: =Inputs!B40*M34 -> 50 | I34: =J34*H34+(1-J34)*G34 -> 45.78472 | J34: =IF(AND($B$4="Yes",K34=1),Inputs!$B$43,0) -> 0 | K34: =IF(AND(A34>=Inputs!$B$9,A34<Inputs!$B$9+Inputs!$B$44),1,0) -> 0 | L34: =(1+Inputs!$B$63)^(A34-$A$8) -> 1.6734181 | M34: =IF(Inputs!$B$64="Yes",L34,1) -> 1 | N34: =IF($A34>=$R$12,T$12,INDEX(T$8:T$12,MATCH($A34,$R$8:$R$12,1))+(INDEX(T$8:T$12,MATCH($A34,$R$8:$R$12,1)+1)-INDEX(T$8:T$12,MATCH($A34,$R$8:$R$12,1)))*($A34-INDEX($R$8:$R$12,MATCH($A34,$R$8:$R$12,1)))/(INDEX($R$8:$R$12,MATCH($A34,$R$8:$R$12,1)+1)-INDEX($R$8:$R$12,MATCH($A34,$R$8:$R$12,1)))) -> 37.4 | O34: =IF($A34>=$R$12,U$12,INDEX(U$8:U$12,MATCH($A34,$R$8:$R$12,1))+(INDEX(U$8:U$12,MATCH($A34,$R$8:$R$12,1)+1)-INDEX(U$8:U$12,MATCH($A34,$R$8:$R$12,1)))*($A34-INDEX($R$8:$R$12,MATCH($A34,$R$8:$R$12,1)))/(INDEX($R$8:$R$12,MATCH($A34,$R$8:$R$12,1)+1)-INDEX($R$8:$R$12,MATCH($A34,$R$8:$R$12,1)))) -> 56.6 | P34: =IF($B$5="Low",N34,IF($B$5="High",O34,B34)) -> 45.6
A35: 2053 | B35: =IF($A35>=$R$12,S$12,INDEX(S$8:S$12,MATCH($A35,$R$8:$R$12,1))+(INDEX(S$8:S$12,MATCH($A35,$R$8:$R$12,1)+1)-INDEX(S$8:S$12,MATCH($A35,$R$8:$R$12,1)))*($A35-INDEX($R$8:$R$12,MATCH($A35,$R$8:$R$12,1)))/(INDEX($R$8:$R$12,MATCH($A35,$R$8:$R$12,1)+1)-INDEX($R$8:$R$12,MATCH($A35,$R$8:$R$12,1)))) -> 45.6 | C35: =Inputs!$B$79 -> 0.5 | D35: =Inputs!$B$80 -> 0.6 | E35: =Inputs!$B$81 -> 0.7 | F35: =IF($B$3="Low",C35,IF($B$3="High",E35,D35)) -> 0.6 | G35: =P35*F35*L35 -> 46.700414 | H35: =Inputs!B40*M35 -> 50 | I35: =J35*H35+(1-J35)*G35 -> 46.700414 | J35: =IF(AND($B$4="Yes",K35=1),Inputs!$B$43,0) -> 0 | K35: =IF(AND(A35>=Inputs!$B$9,A35<Inputs!$B$9+Inputs!$B$44),1,0) -> 0 | L35: =(1+Inputs!$B$63)^(A35-$A$8) -> 1.7068865 | M35: =IF(Inputs!$B$64="Yes",L35,1) -> 1 | N35: =IF($A35>=$R$12,T$12,INDEX(T$8:T$12,MATCH($A35,$R$8:$R$12,1))+(INDEX(T$8:T$12,MATCH($A35,$R$8:$R$12,1)+1)-INDEX(T$8:T$12,MATCH($A35,$R$8:$R$12,1)))*($A35-INDEX($R$8:$R$12,MATCH($A35,$R$8:$R$12,1)))/(INDEX($R$8:$R$12,MATCH($A35,$R$8:$R$12,1)+1)-INDEX($R$8:$R$12,MATCH($A35,$R$8:$R$12,1)))) -> 37.4 | O35: =IF($A35>=$R$12,U$12,INDEX(U$8:U$12,MATCH($A35,$R$8:$R$12,1))+(INDEX(U$8:U$12,MATCH($A35,$R$8:$R$12,1)+1)-INDEX(U$8:U$12,MATCH($A35,$R$8:$R$12,1)))*($A35-INDEX($R$8:$R$12,MATCH($A35,$R$8:$R$12,1)))/(INDEX($R$8:$R$12,MATCH($A35,$R$8:$R$12,1)+1)-INDEX($R$8:$R$12,MATCH($A35,$R$8:$R$12,1)))) -> 56.6 | P35: =IF($B$5="Low",N35,IF($B$5="High",O35,B35)) -> 45.6
